Workbook
Name Ишчи_ҳолатида: 'жами банкоматлар 2025'!#REF!
Name Ишчи_ҳолатида: #REF!

Sheet жами банкоматлар 2025
T1: 45703 | V1: 45716 | X1: 45777 | Z1: 45792 | AB1: 45823 | AD1: 45838 | AF1: 45853 | AH1: 45869 | AJ1: 45886 | AL1: 45930
A2: № | B2: № | C2: МФО | D2: МФО | E2: Худуд | F2: Филиал | G2: Модели | I2: Тўлов тизими тури | J2: Серия рақами | K2: Сотиб олинган сана | L2: M.B | M2: Инвентар id рақами | N2: Merchant id | O2: Term id | P2: МФО | Q2: Манзили | R2: Геолокация (alt) | S2: Геолокация (long) | T2: покупка | U2: продажа | V2: покупка | W2: продажа | X2: покупка | Y2: продажа | Z2: покупка | AA2: продажа | AB2: покупка | AC2: продажа | AD2: покупка | AE2: продажа | AF2: покупка | AG2: продажа | AH2: покупка | AI2: продажа | AJ2: покупка | AK2: продажа | AL2: покупка | AM2: продажа
A3: 1 | B3: 1 | C3: 00051 | D3: 11087 | E3: Андижон вилояти | F3: Хонобод БХМ | G3: NCR 6623 | H3: CashOut | I3: UzCard | J3: 57208979 | K3: 2019 йил август ойи | M3: 0051-01 | N3: 900333415 | O3: 34884 | P3: 00051 | Q3: Андижон вилояти, Хонобод шахар, Истиқлол МФЙ Фароғат кўчаси 2-уй | R3: 40.803249 | S3: 72.987511

Sheet Раисга
A1: № | B1: Худуд номи | C1: Жами | D1: Банкоматлар сони, шундан: | L1: Инфокиосклар сони, шундан:
D2: UZCARD | H2: HUMO | J2: Way4
D3: Нақд пул бериш | E3: Нақд пул бериш/қабул қилиш (ВАШ) | F3: Узкард карталари орқали коммунал ва бир марталик тўловларни амалга ошириш мумкин | G3: Узкарт карталари орқали АҚШ валютасини сотиш | H3: Нақд пул бериш | I3: Нақд пул бериш/қабул қилиш | J3: Нақд пул бериш | K3: Нақд пул бериш/қабул қилиш
A4: 1 | B4: Қорақалпоғистон Республикаси | C4: =D4+E4+H4+I4+J4+K4 -> 0 | D4: =COUNTIFS('жами банкоматлар 2025'!$E:$E,$B4,'жами банкоматлар 2025'!$I:$I,"UzCard",'жами банкоматлар 2025'!$G:$G,"NCR 6623")+COUNTIFS('жами банкоматлар 2025'!$E:$E,$B4,'жами банкоматлар 2025'!$I:$I,"UzCard",'жами банкоматлар 2025'!$G:$G,"NCR 6622") -> 0 | E4: =COUNTIFS('жами банкоматлар 2025'!$E:$E,$B4,'жами банкоматлар 2025'!$I:$I,"UzCard",'жами банкоматлар 2025'!$G:$G,"CINEO C2070")+COUNTIFS('жами банкоматлар 2025'!$E:$E,$B4,'жами банкоматлар 2025'!$I:$I,"UzCard",'жами банкоматлар 2025'!$G:$G,"CINEO C4560") -> 0 | F4: 7 | G4: 0 | H4: =COUNTIFS('жами банкоматлар 2025'!$E:$E,$B4,'жами банкоматлар 2025'!$I:$I,"Humo",'жами банкоматлар 2025'!$G:$G,"NCR 6623")+COUNTIFS('жами банкоматлар 2025'!$E:$E,$B4,'жами банкоматлар 2025'!$I:$I,"Humo",'жами банкоматлар 2025'!$G:$G,"CINEO C2040") -> 0 | I4: =COUNTIFS('жами банкоматлар 2025'!$E:$E,$B4,'жами банкоматлар 2025'!$I:$I,"Humo",'жами банкоматлар 2025'!$G:$G,"NCR 6682")+COUNTIFS('жами банкоматлар 2025'!$E:$E,$B4,'жами банкоматлар 2025'!$I:$I,"Humo",'жами банкоматлар 2025'!$G:$G,"CINEO C2070")+COUNTIFS('жами банкоматлар 2025'!$E:$E,$B4,'жами банкоматлар 2025'!$I:$I,"Humo",'жами банкоматлар 2025'!$G:$G,"GRG P5800") -> 0 | J4: =COUNTIFS('жами банкоматлар 2025'!$E:$E,$B4,'жами банкоматлар 2025'!$I:$I,"WAY4",'жами банкоматлар 2025'!$G:$G,"NCR 6623") -> 0 | K4: =COUNTIFS('жами банкоматлар 2025'!$E:$E,$B4,'жами банкоматлар 2025'!$I:$I,"WAY4",'жами банкоматлар 2025'!$G:$G,"NCR 6682")+COUNTIFS('жами банкоматлар 2025'!$E:$E,$B4,'жами банкоматлар 2025'!$I:$I,"WAY4",'жами банкоматлар 2025'!$G:$G,"CINEO C2070")+COUNTIFS('жами банкоматлар 2025'!$E:$E,$B4,'жами банкоматлар 2025'!$I:$I,"WAY4",'жами банкоматлар 2025'!$G:$G,"GRG P5800") -> 0 | L4: =COUNTIFS(Инфокиоски!$E:$E,$B4,Инфокиоски!$D:$D,"Touchplat")+COUNTIFS(Инфокиоски!$E:$E,$B4,Инфокиоски!$D:$D,"Optimal") -> 12
A5: 2 | B5: Андижон вилояти | C5: =D5+E5+H5+I5+J5+K5 -> 1 | D5: =COUNTIFS('жами банкоматлар 2025'!$E:$E,$B5,'жами банкоматлар 2025'!$I:$I,"UzCard",'жами банкоматлар 2025'!$G:$G,"NCR 6623")+COUNTIFS('жами банкоматлар 2025'!$E:$E,$B5,'жами банкоматлар 2025'!$I:$I,"UzCard",'жами банкоматлар 2025'!$G:$G,"NCR 6622") -> 1 | E5: =COUNTIFS('жами банкоматлар 2025'!$E:$E,$B5,'жами банкоматлар 2025'!$I:$I,"UzCard",'жами банкоматлар 2025'!$G:$G,"CINEO C2070")+COUNTIFS('жами банкоматлар 2025'!$E:$E,$B5,'жами банкоматлар 2025'!$I:$I,"UzCard",'жами банкоматлар 2025'!$G:$G,"CINEO C4560") -> 0 | F5: 10 | G5: 0 | H5: =COUNTIFS('жами банкоматлар 2025'!$E:$E,$B5,'жами банкоматлар 2025'!$I:$I,"Humo",'жами банкоматлар 2025'!$G:$G,"NCR 6623")+COUNTIFS('жами банкоматлар 2025'!$E:$E,$B5,'жами банкоматлар 2025'!$I:$I,"Humo",'жами банкоматлар 2025'!$G:$G,"CINEO C2040") -> 0 | I5: =COUNTIFS('жами банкоматлар 2025'!$E:$E,$B5,'жами банкоматлар 2025'!$I:$I,"Humo",'жами банкоматлар 2025'!$G:$G,"NCR 6682")+COUNTIFS('жами банкоматлар 2025'!$E:$E,$B5,'жами банкоматлар 2025'!$I:$I,"Humo",'жами банкоматлар 2025'!$G:$G,"CINEO C2070")+COUNTIFS('жами банкоматлар 2025'!$E:$E,$B5,'жами банкоматлар 2025'!$I:$I,"Humo",'жами банкоматлар 2025'!$G:$G,"GRG P5800") -> 0 | J5: =COUNTIFS('жами банкоматлар 2025'!$E:$E,$B5,'жами банкоматлар 2025'!$I:$I,"WAY4",'жами банкоматлар 2025'!$G:$G,"NCR 6623") -> 0 | K5: =COUNTIFS('жами банкоматлар 2025'!$E:$E,$B5,'жами банкоматлар 2025'!$I:$I,"WAY4",'жами банкоматлар 2025'!$G:$G,"NCR 6682")+COUNTIFS('жами банкоматлар 2025'!$E:$E,$B5,'жами банкоматлар 2025'!$I:$I,"WAY4",'жами банкоматлар 2025'!$G:$G,"CINEO C2070")+COUNTIFS('жами банкоматлар 2025'!$E:$E,$B5,'жами банкоматлар 2025'!$I:$I,"WAY4",'жами банкоматлар 2025'!$G:$G,"GRG P5800") -> 0 | L5: =COUNTIFS(Инфокиоски!$E:$E,$B5,Инфокиоски!$D:$D,"Touchplat")+COUNTIFS(Инфокиоски!$E:$E,$B5,Инфокиоски!$D:$D,"Optimal") -> 10
A6: 3 | B6: Бухоро вилояти | C6: =D6+E6+H6+I6+J6+K6 -> 0 | D6: =COUNTIFS('жами банкоматлар 2025'!$E:$E,$B6,'жами банкоматлар 2025'!$I:$I,"UzCard",'жами банкоматлар 2025'!$G:$G,"NCR 6623")+COUNTIFS('жами банкоматлар 2025'!$E:$E,$B6,'жами банкоматлар 2025'!$I:$I,"UzCard",'жами банкоматлар 2025'!$G:$G,"NCR 6622") -> 0 | E6: =COUNTIFS('жами банкоматлар 2025'!$E:$E,$B6,'жами банкоматлар 2025'!$I:$I,"UzCard",'жами банкоматлар 2025'!$G:$G,"CINEO C2070")+COUNTIFS('жами банкоматлар 2025'!$E:$E,$B6,'жами банкоматлар 2025'!$I:$I,"UzCard",'жами банкоматлар 2025'!$G:$G,"CINEO C4560") -> 0 | F6: 10 | G6: 0 | H6: =COUNTIFS('жами банкоматлар 2025'!$E:$E,$B6,'жами банкоматлар 2025'!$I:$I,"Humo",'жами банкоматлар 2025'!$G:$G,"NCR 6623")+COUNTIFS('жами банкоматлар 2025'!$E:$E,$B6,'жами банкоматлар 2025'!$I:$I,"Humo",'жами банкоматлар 2025'!$G:$G,"CINEO C2040") -> 0 | I6: =COUNTIFS('жами банкоматлар 2025'!$E:$E,$B6,'жами банкоматлар 2025'!$I:$I,"Humo",'жами банкоматлар 2025'!$G:$G,"NCR 6682")+COUNTIFS('жами банкоматлар 2025'!$E:$E,$B6,'жами банкоматлар 2025'!$I:$I,"Humo",'жами банкоматлар 2025'!$G:$G,"CINEO C2070")+COUNTIFS('жами банкоматлар 2025'!$E:$E,$B6,'жами банкоматлар 2025'!$I:$I,"Humo",'жами банкоматлар 2025'!$G:$G,"GRG P5800") -> 0 | J6: =COUNTIFS('жами банкоматлар 2025'!$E:$E,$B6,'жами банкоматлар 2025'!$I:$I,"WAY4",'жами банкоматлар 2025'!$G:$G,"NCR 6623") -> 0 | K6: =COUNTIFS('жами банкоматлар 2025'!$E:$E,$B6,'жами банкоматлар 2025'!$I:$I,"WAY4",'жами банкоматлар 2025'!$G:$G,"NCR 6682")+COUNTIFS('жами банкоматлар 2025'!$E:$E,$B6,'жами банкоматлар 2025'!$I:$I,"WAY4",'жами банкоматлар 2025'!$G:$G,"CINEO C2070")+COUNTIFS('жами банкоматлар 2025'!$E:$E,$B6,'жами банкоматлар 2025'!$I:$I,"WAY4",'жами банкоматлар 2025'!$G:$G,"GRG P5800") -> 0 | L6: =COUNTIFS(Инфокиоски!$E:$E,$B6,Инфокиоски!$D:$D,"Touchplat")+COUNTIFS(Инфокиоски!$E:$E,$B6,Инфокиоски!$D:$D,"Optimal") -> 6
A7: 4 | B7: Жиззах вилояти | C7: =D7+E7+H7+I7+J7+K7 -> 0 | D7: =COUNTIFS('жами банкоматлар 2025'!$E:$E,$B7,'жами банкоматлар 2025'!$I:$I,"UzCard",'жами банкоматлар 2025'!$G:$G,"NCR 6623")+COUNTIFS('жами банкоматлар 2025'!$E:$E,$B7,'жами банкоматлар 2025'!$I:$I,"UzCard",'жами банкоматлар 2025'!$G:$G,"NCR 6622") -> 0 | E7: =COUNTIFS('жами банкоматлар 2025'!$E:$E,$B7,'жами банкоматлар 2025'!$I:$I,"UzCard",'жами банкоматлар 2025'!$G:$G,"CINEO C2070")+COUNTIFS('жами банкоматлар 2025'!$E:$E,$B7,'жами банкоматлар 2025'!$I:$I,"UzCard",'жами банкоматлар 2025'!$G:$G,"CINEO C4560") -> 0 | F7: 5 | G7: 0 | H7: =COUNTIFS('жами банкоматлар 2025'!$E:$E,$B7,'жами банкоматлар 2025'!$I:$I,"Humo",'жами банкоматлар 2025'!$G:$G,"NCR 6623")+COUNTIFS('жами банкоматлар 2025'!$E:$E,$B7,'жами банкоматлар 2025'!$I:$I,"Humo",'жами банкоматлар 2025'!$G:$G,"CINEO C2040") -> 0 | I7: =COUNTIFS('жами банкоматлар 2025'!$E:$E,$B7,'жами банкоматлар 2025'!$I:$I,"Humo",'жами банкоматлар 2025'!$G:$G,"NCR 6682")+COUNTIFS('жами банкоматлар 2025'!$E:$E,$B7,'жами банкоматлар 2025'!$I:$I,"Humo",'жами банкоматлар 2025'!$G:$G,"CINEO C2070")+COUNTIFS('жами банкоматлар 2025'!$E:$E,$B7,'жами банкоматлар 2025'!$I:$I,"Humo",'жами банкоматлар 2025'!$G:$G,"GRG P5800") -> 0 | J7: =COUNTIFS('жами банкоматлар 2025'!$E:$E,$B7,'жами банкоматлар 2025'!$I:$I,"WAY4",'жами банкоматлар 2025'!$G:$G,"NCR 6623") -> 0 | K7: =COUNTIFS('жами банкоматлар 2025'!$E:$E,$B7,'жами банкоматлар 2025'!$I:$I,"WAY4",'жами банкоматлар 2025'!$G:$G,"NCR 6682")+COUNTIFS('жами банкоматлар 2025'!$E:$E,$B7,'жами банкоматлар 2025'!$I:$I,"WAY4",'жами банкоматлар 2025'!$G:$G,"CINEO C2070")+COUNTIFS('жами банкоматлар 2025'!$E:$E,$B7,'жами банкоматлар 2025'!$I:$I,"WAY4",'жами банкоматлар 2025'!$G:$G,"GRG P5800") -> 0 | L7: =COUNTIFS(Инфокиоски!$E:$E,$B7,Инфокиоски!$D:$D,"Touchplat")+COUNTIFS(Инфокиоски!$E:$E,$B7,Инфокиоски!$D:$D,"Optimal") -> 2
A8: 5 | B8: Қашқадарё вилояти | C8: =D8+E8+H8+I8+J8+K8 -> 0 | D8: =COUNTIFS('жами банкоматлар 2025'!$E:$E,$B8,'жами банкоматлар 2025'!$I:$I,"UzCard",'жами банкоматлар 2025'!$G:$G,"NCR 6623")+COUNTIFS('жами банкоматлар 2025'!$E:$E,$B8,'жами банкоматлар 2025'!$I:$I,"UzCard",'жами банкоматлар 2025'!$G:$G,"NCR 6622") -> 0 | E8: =COUNTIFS('жами банкоматлар 2025'!$E:$E,$B8,'жами банкоматлар 2025'!$I:$I,"UzCard",'жами банкоматлар 2025'!$G:$G,"CINEO C2070")+COUNTIFS('жами банкоматлар 2025'!$E:$E,$B8,'жами банкоматлар 2025'!$I:$I,"UzCard",'жами банкоматлар 2025'!$G:$G,"CINEO C4560") -> 0 | F8: 8 | G8: 0 | H8: =COUNTIFS('жами банкоматлар 2025'!$E:$E,$B8,'жами банкоматлар 2025'!$I:$I,"Humo",'жами банкоматлар 2025'!$G:$G,"NCR 6623")+COUNTIFS('жами банкоматлар 2025'!$E:$E,$B8,'жами банкоматлар 2025'!$I:$I,"Humo",'жами банкоматлар 2025'!$G:$G,"CINEO C2040") -> 0 | I8: =COUNTIFS('жами банкоматлар 2025'!$E:$E,$B8,'жами банкоматлар 2025'!$I:$I,"Humo",'жами банкоматлар 2025'!$G:$G,"NCR 6682")+COUNTIFS('жами банкоматлар 2025'!$E:$E,$B8,'жами банкоматлар 2025'!$I:$I,"Humo",'жами банкоматлар 2025'!$G:$G,"CINEO C2070")+COUNTIFS('жами банкоматлар 2025'!$E:$E,$B8,'жами банкоматлар 2025'!$I:$I,"Humo",'жами банкоматлар 2025'!$G:$G,"GRG P5800") -> 0 | J8: =COUNTIFS('жами банкоматлар 2025'!$E:$E,$B8,'жами банкоматлар 2025'!$I:$I,"WAY4",'жами банкоматлар 2025'!$G:$G,"NCR 6623") -> 0 | K8: =COUNTIFS('жами банкоматлар 2025'!$E:$E,$B8,'жами банкоматлар 2025'!$I:$I,"WAY4",'жами банкоматлар 2025'!$G:$G,"NCR 6682")+COUNTIFS('жами банкоматлар 2025'!$E:$E,$B8,'жами банкоматлар 2025'!$I:$I,"WAY4",'жами банкоматлар 2025'!$G:$G,"CINEO C2070")+COUNTIFS('жами банкоматлар 2025'!$E:$E,$B8,'жами банкоматлар 2025'!$I:$I,"WAY4",'жами банкоматлар 2025'!$G:$G,"GRG P5800") -> 0 | L8: =COUNTIFS(Инфокиоски!$E:$E,$B8,Инфокиоски!$D:$D,"Touchplat")+COUNTIFS(Инфокиоски!$E:$E,$B8,Инфокиоски!$D:$D,"Optimal") -> 12
A9: 6 | B9: Навоий вилояти | C9: =D9+E9+H9+I9+J9+K9 -> 0 | D9: =COUNTIFS('жами банкоматлар 2025'!$E:$E,$B9,'жами банкоматлар 2025'!$I:$I,"UzCard",'жами банкоматлар 2025'!$G:$G,"NCR 6623")+COUNTIFS('жами банкоматлар 2025'!$E:$E,$B9,'жами банкоматлар 2025'!$I:$I,"UzCard",'жами банкоматлар 2025'!$G:$G,"NCR 6622") -> 0 | E9: =COUNTIFS('жами банкоматлар 2025'!$E:$E,$B9,'жами банкоматлар 2025'!$I:$I,"UzCard",'жами банкоматлар 2025'!$G:$G,"CINEO C2070")+COUNTIFS('жами банкоматлар 2025'!$E:$E,$B9,'жами банкоматлар 2025'!$I:$I,"UzCard",'жами банкоматлар 2025'!$G:$G,"NCR 6682") -> 0 | F9: 7 | G9: 0 | H9: =COUNTIFS('жами банкоматлар 2025'!$E:$E,$B9,'жами банкоматлар 2025'!$I:$I,"Humo",'жами банкоматлар 2025'!$G:$G,"NCR 6623")+COUNTIFS('жами банкоматлар 2025'!$E:$E,$B9,'жами банкоматлар 2025'!$I:$I,"Humo",'жами банкоматлар 2025'!$G:$G,"CINEO C2040") -> 0 | I9: =COUNTIFS('жами банкоматлар 2025'!$E:$E,$B9,'жами банкоматлар 2025'!$I:$I,"Humo",'жами банкоматлар 2025'!$G:$G,"NCR 6682")+COUNTIFS('жами банкоматлар 2025'!$E:$E,$B9,'жами банкоматлар 2025'!$I:$I,"Humo",'жами банкоматлар 2025'!$G:$G,"CINEO C2070")+COUNTIFS('жами банкоматлар 2025'!$E:$E,$B9,'жами банкоматлар 2025'!$I:$I,"Humo",'жами банкоматлар 2025'!$G:$G,"GRG P5800") -> 0 | J9: =COUNTIFS('жами банкоматлар 2025'!$E:$E,$B9,'жами банкоматлар 2025'!$I:$I,"WAY4",'жами банкоматлар 2025'!$G:$G,"NCR 6623") -> 0 | K9: =COUNTIFS('жами банкоматлар 2025'!$E:$E,$B9,'жами банкоматлар 2025'!$I:$I,"WAY4",'жами банкоматлар 2025'!$G:$G,"NCR 6682")+COUNTIFS('жами банкоматлар 2025'!$E:$E,$B9,'жами банкоматлар 2025'!$I:$I,"WAY4",'жами банкоматлар 2025'!$G:$G,"CINEO C2070")+COUNTIFS('жами банкоматлар 2025'!$E:$E,$B9,'жами банкоматлар 2025'!$I:$I,"WAY4",'жами банкоматлар 2025'!$G:$G,"GRG P5800") -> 0 | L9: =COUNTIFS(Инфокиоски!$E:$E,$B9,Инфокиоски!$D:$D,"Touchplat")+COUNTIFS(Инфокиоски!$E:$E,$B9,Инфокиоски!$D:$D,"Optimal") -> 4
A10: 7 | B10: Наманган вилояти | C10: =D10+E10+H10+I10+J10+K10 -> 0 | D10: =COUNTIFS('жами банкоматлар 2025'!$E:$E,$B10,'жами банкоматлар 2025'!$I:$I,"UzCard",'жами банкоматлар 2025'!$G:$G,"NCR 6623")+COUNTIFS('жами банкоматлар 2025'!$E:$E,$B10,'жами банкоматлар 2025'!$I:$I,"UzCard",'жами банкоматлар 2025'!$G:$G,"NCR 6622") -> 0 | E10: =COUNTIFS('жами банкоматлар 2025'!$E:$E,$B10,'жами банкоматлар 2025'!$I:$I,"UzCard",'жами банкоматлар 2025'!$G:$G,"CINEO C2070")+COUNTIFS('жами банкоматлар 2025'!$E:$E,$B10,'жами банкоматлар 2025'!$I:$I,"UzCard",'жами банкоматлар 2025'!$G:$G,"CINEO C4560") -> 0 | F10: 5 | G10: 0 | H10: =COUNTIFS('жами банкоматлар 2025'!$E:$E,$B10,'жами банкоматлар 2025'!$I:$I,"Humo",'жами банкоматлар 2025'!$G:$G,"NCR 6623")+COUNTIFS('жами банкоматлар 2025'!$E:$E,$B10,'жами банкоматлар 2025'!$I:$I,"Humo",'жами банкоматлар 2025'!$G:$G,"CINEO C2040") -> 0 | I10: =COUNTIFS('жами банкоматлар 2025'!$E:$E,$B10,'жами банкоматлар 2025'!$I:$I,"Humo",'жами банкоматлар 2025'!$G:$G,"NCR 6682")+COUNTIFS('жами банкоматлар 2025'!$E:$E,$B10,'жами банкоматлар 2025'!$I:$I,"Humo",'жами банкоматлар 2025'!$G:$G,"CINEO C2070")+COUNTIFS('жами банкоматлар 2025'!$E:$E,$B10,'жами банкоматлар 2025'!$I:$I,"Humo",'жами банкоматлар 2025'!$G:$G,"GRG P5800") -> 0 | J10: =COUNTIFS('жами банкоматлар 2025'!$E:$E,$B10,'жами банкоматлар 2025'!$I:$I,"WAY4",'жами банкоматлар 2025'!$G:$G,"NCR 6623") -> 0 | K10: =COUNTIFS('жами банкоматлар 2025'!$E:$E,$B10,'жами банкоматлар 2025'!$I:$I,"WAY4",'жами банкоматлар 2025'!$G:$G,"NCR 6682")+COUNTIFS('жами банкоматлар 2025'!$E:$E,$B10,'жами банкоматлар 2025'!$I:$I,"WAY4",'жами банкоматлар 2025'!$G:$G,"CINEO C2070")+COUNTIFS('жами банкоматлар 2025'!$E:$E,$B10,'жами банкоматлар 2025'!$I:$I,"WAY4",'жами банкоматлар 2025'!$G:$G,"GRG P5800") -> 0 | L10: =COUNTIFS(Инфокиоски!$E:$E,$B10,Инфокиоски!$D:$D,"Touchplat")+COUNTIFS(Инфокиоски!$E:$E,$B10,Инфокиоски!$D:$D,"Optimal") -> 4
A11: 8 | B11: Самарқанд вилояти | C11: =D11+E11+H11+I11+J11+K11 -> 0 | D11: =COUNTIFS('жами банкоматлар 2025'!$E:$E,$B11,'жами банкоматлар 2025'!$I:$I,"UzCard",'жами банкоматлар 2025'!$G:$G,"NCR 6623")+COUNTIFS('жами банкоматлар 2025'!$E:$E,$B11,'жами банкоматлар 2025'!$I:$I,"UzCard",'жами банкоматлар 2025'!$G:$G,"NCR 6622") -> 0 | E11: =COUNTIFS('жами банкоматлар 2025'!$E:$E,$B11,'жами банкоматлар 2025'!$I:$I,"UzCard",'жами банкоматлар 2025'!$G:$G,"CINEO C2070")+COUNTIFS('жами банкоматлар 2025'!$E:$E,$B11,'жами банкоматлар 2025'!$I:$I,"UzCard",'жами банкоматлар 2025'!$G:$G,"CINEO C4560") -> 0 | F11: 3 | G11: 0 | H11: =COUNTIFS('жами банкоматлар 2025'!$E:$E,$B11,'жами банкоматлар 2025'!$I:$I,"Humo",'жами банкоматлар 2025'!$G:$G,"NCR 6623")+COUNTIFS('жами банкоматлар 2025'!$E:$E,$B11,'жами банкоматлар 2025'!$I:$I,"Humo",'жами банкоматлар 2025'!$G:$G,"CINEO C2040") -> 0 | I11: =COUNTIFS('жами банкоматлар 2025'!$E:$E,$B11,'жами банкоматлар 2025'!$I:$I,"Humo",'жами банкоматлар 2025'!$G:$G,"NCR 6682")+COUNTIFS('жами банкоматлар 2025'!$E:$E,$B11,'жами банкоматлар 2025'!$I:$I,"Humo",'жами банкоматлар 2025'!$G:$G,"CINEO C2070")+COUNTIFS('жами банкоматлар 2025'!$E:$E,$B11,'жами банкоматлар 2025'!$I:$I,"Humo",'жами банкоматлар 2025'!$G:$G,"GRG P5800") -> 0 | J11: =COUNTIFS('жами банкоматлар 2025'!$E:$E,$B11,'жами банкоматлар 2025'!$I:$I,"WAY4",'жами банкоматлар 2025'!$G:$G,"NCR 6623") -> 0 | K11: =COUNTIFS('жами банкоматлар 2025'!$E:$E,$B11,'жами банкоматлар 2025'!$I:$I,"WAY4",'жами банкоматлар 2025'!$G:$G,"NCR 6682")+COUNTIFS('жами банкоматлар 2025'!$E:$E,$B11,'жами банкоматлар 2025'!$I:$I,"WAY4",'жами банкоматлар 2025'!$G:$G,"CINEO C2070")+COUNTIFS('жами банкоматлар 2025'!$E:$E,$B11,'жами банкоматлар 2025'!$I:$I,"WAY4",'жами банкоматлар 2025'!$G:$G,"GRG P5800") -> 0 | L11: =COUNTIFS(Инфокиоски!$E:$E,$B11,Инфокиоски!$D:$D,"Touchplat")+COUNTIFS(Инфокиоски!$E:$E,$B11,Инфокиоски!$D:$D,"Optimal") -> 2
A12: 9 | B12: Сирдарё вилояти | C12: =D12+E12+H12+I12+J12+K12 -> 0 | D12: =COUNTIFS('жами банкоматлар 2025'!$E:$E,$B12,'жами банкоматлар 2025'!$I:$I,"UzCard",'жами банкоматлар 2025'!$G:$G,"NCR 6623")+COUNTIFS('жами банкоматлар 2025'!$E:$E,$B12,'жами банкоматлар 2025'!$I:$I,"UzCard",'жами банкоматлар 2025'!$G:$G,"NCR 6622") -> 0 | E12: =COUNTIFS('жами банкоматлар 2025'!$E:$E,$B12,'жами банкоматлар 2025'!$I:$I,"UzCard",'жами банкоматлар 2025'!$G:$G,"CINEO C2070")+COUNTIFS('жами банкоматлар 2025'!$E:$E,$B12,'жами банкоматлар 2025'!$I:$I,"UzCard",'жами банкоматлар 2025'!$G:$G,"CINEO C4560") -> 0 | F12: 4 | G12: 0 | H12: =COUNTIFS('жами банкоматлар 2025'!$E:$E,$B12,'жами банкоматлар 2025'!$I:$I,"Humo",'жами банкоматлар 2025'!$G:$G,"NCR 6623")+COUNTIFS('жами банкоматлар 2025'!$E:$E,$B12,'жами банкоматлар 2025'!$I:$I,"Humo",'жами банкоматлар 2025'!$G:$G,"CINEO C2040") -> 0 | I12: =COUNTIFS('жами банкоматлар 2025'!$E:$E,$B12,'жами банкоматлар 2025'!$I:$I,"Humo",'жами банкоматлар 2025'!$G:$G,"NCR 6682")+COUNTIFS('жами банкоматлар 2025'!$E:$E,$B12,'жами банкоматлар 2025'!$I:$I,"Humo",'жами банкоматлар 2025'!$G:$G,"CINEO C2070")+COUNTIFS('жами банкоматлар 2025'!$E:$E,$B12,'жами банкоматлар 2025'!$I:$I,"Humo",'жами банкоматлар 2025'!$G:$G,"GRG P5800") -> 0 | J12: =COUNTIFS('жами банкоматлар 2025'!$E:$E,$B12,'жами банкоматлар 2025'!$I:$I,"WAY4",'жами банкоматлар 2025'!$G:$G,"NCR 6623") -> 0 | K12: =COUNTIFS('жами банкоматлар 2025'!$E:$E,$B12,'жами банкоматлар 2025'!$I:$I,"WAY4",'жами банкоматлар 2025'!$G:$G,"NCR 6682")+COUNTIFS('жами банкоматлар 2025'!$E:$E,$B12,'жами банкоматлар 2025'!$I:$I,"WAY4",'жами банкоматлар 2025'!$G:$G,"CINEO C2070")+COUNTIFS('жами банкоматлар 2025'!$E:$E,$B12,'жами банкоматлар 2025'!$I:$I,"WAY4",'жами банкоматлар 2025'!$G:$G,"GRG P5800") -> 0 | L12: =COUNTIFS(Инфокиоски!$E:$E,$B12,Инфокиоски!$D:$D,"Touchplat")+COUNTIFS(Инфокиоски!$E:$E,$B12,Инфокиоски!$D:$D,"Optimal") -> 3
A13: 10 | B13: Сурхондарё вилояти | C13: =D13+E13+H13+I13+J13+K13 -> 0 | D13: =COUNTIFS('жами банкоматлар 2025'!$E:$E,$B13,'жами банкоматлар 2025'!$I:$I,"UzCard",'жами банкоматлар 2025'!$G:$G,"NCR 6623")+COUNTIFS('жами банкоматлар 2025'!$E:$E,$B13,'жами банкоматлар 2025'!$I:$I,"UzCard",'жами банкоматлар 2025'!$G:$G,"NCR 6622") -> 0 | E13: =COUNTIFS('жами банкоматлар 2025'!$E:$E,$B13,'жами банкоматлар 2025'!$I:$I,"UzCard",'жами банкоматлар 2025'!$G:$G,"CINEO C2070")+COUNTIFS('жами банкоматлар 2025'!$E:$E,$B13,'жами банкоматлар 2025'!$I:$I,"UzCard",'жами банкоматлар 2025'!$G:$G,"CINEO C4560") -> 0 | F13: 7 | G13: 0 | H13: =COUNTIFS('жами банкоматлар 2025'!$E:$E,$B13,'жами банкоматлар 2025'!$I:$I,"Humo",'жами банкоматлар 2025'!$G:$G,"NCR 6623")+COUNTIFS('жами банкоматлар 2025'!$E:$E,$B13,'жами банкоматлар 2025'!$I:$I,"Humo",'жами банкоматлар 2025'!$G:$G,"CINEO C2040") -> 0 | I13: =COUNTIFS('жами банкоматлар 2025'!$E:$E,$B13,'жами банкоматлар 2025'!$I:$I,"Humo",'жами банкоматлар 2025'!$G:$G,"NCR 6682")+COUNTIFS('жами банкоматлар 2025'!$E:$E,$B13,'жами банкоматлар 2025'!$I:$I,"Humo",'жами банкоматлар 2025'!$G:$G,"CINEO C2070")+COUNTIFS('жами банкоматлар 2025'!$E:$E,$B13,'жами банкоматлар 2025'!$I:$I,"Humo",'жами банкоматлар 2025'!$G:$G,"GRG P5800") -> 0 | J13: =COUNTIFS('жами банкоматлар 2025'!$E:$E,$B13,'жами банкоматлар 2025'!$I:$I,"WAY4",'жами банкоматлар 2025'!$G:$G,"NCR 6623") -> 0 | K13: =COUNTIFS('жами банкоматлар 2025'!$E:$E,$B13,'жами банкоматлар 2025'!$I:$I,"WAY4",'жами банкоматлар 2025'!$G:$G,"NCR 6682")+COUNTIFS('жами банкоматлар 2025'!$E:$E,$B13,'жами банкоматлар 2025'!$I:$I,"WAY4",'жами банкоматлар 2025'!$G:$G,"CINEO C2070")+COUNTIFS('жами банкоматлар 2025'!$E:$E,$B13,'жами банкоматлар 2025'!$I:$I,"WAY4",'жами банкоматлар 2025'!$G:$G,"GRG P5800") -> 0 | L13: =COUNTIFS(Инфокиоски!$E:$E,$B13,Инфокиоски!$D:$D,"Touchplat")+COUNTIFS(Инфокиоски!$E:$E,$B13,Инфокиоски!$D:$D,"Optimal") -> 7
A14: 11 | B14: Тошкент вилояти | C14: =D14+E14+H14+I14+J14+K14 -> 0 | D14: =COUNTIFS('жами банкоматлар 2025'!$E:$E,$B14,'жами банкоматлар 2025'!$I:$I,"UzCard",'жами банкоматлар 2025'!$G:$G,"NCR 6623")+COUNTIFS('жами банкоматлар 2025'!$E:$E,$B14,'жами банкоматлар 2025'!$I:$I,"UzCard",'жами банкоматлар 2025'!$G:$G,"NCR 6622") -> 0 | E14: =COUNTIFS('жами банкоматлар 2025'!$E:$E,$B14,'жами банкоматлар 2025'!$I:$I,"UzCard",'жами банкоматлар 2025'!$G:$G,"CINEO C2070")+COUNTIFS('жами банкоматлар 2025'!$E:$E,$B14,'жами банкоматлар 2025'!$I:$I,"UzCard",'жами банкоматлар 2025'!$G:$G,"CINEO C4560") -> 0 | F14: 20 | G14: 0 | H14: =COUNTIFS('жами банкоматлар 2025'!$E:$E,$B14,'жами банкоматлар 2025'!$I:$I,"Humo",'жами банкоматлар 2025'!$G:$G,"NCR 6623")+COUNTIFS('жами банкоматлар 2025'!$E:$E,$B14,'жами банкоматлар 2025'!$I:$I,"Humo",'жами банкоматлар 2025'!$G:$G,"CINEO C2040") -> 0 | I14: =COUNTIFS('жами банкоматлар 2025'!$E:$E,$B14,'жами банкоматлар 2025'!$I:$I,"Humo",'жами банкоматлар 2025'!$G:$G,"NCR 6682")+COUNTIFS('жами банкоматлар 2025'!$E:$E,$B14,'жами банкоматлар 2025'!$I:$I,"Humo",'жами банкоматлар 2025'!$G:$G,"CINEO C2070")+COUNTIFS('жами банкоматлар 2025'!$E:$E,$B14,'жами банкоматлар 2025'!$I:$I,"Humo",'жами банкоматлар 2025'!$G:$G,"GRG P5800") -> 0 | J14: =COUNTIFS('жами банкоматлар 2025'!$E:$E,$B14,'жами банкоматлар 2025'!$I:$I,"WAY4",'жами банкоматлар 2025'!$G:$G,"NCR 6623") -> 0 | K14: =COUNTIFS('жами банкоматлар 2025'!$E:$E,$B14,'жами банкоматлар 2025'!$I:$I,"WAY4",'жами банкоматлар 2025'!$G:$G,"NCR 6682")+COUNTIFS('жами банкоматлар 2025'!$E:$E,$B14,'жами банкоматлар 2025'!$I:$I,"WAY4",'жами банкоматлар 2025'!$G:$G,"CINEO C2070")+COUNTIFS('жами банкоматлар 2025'!$E:$E,$B14,'жами банкоматлар 2025'!$I:$I,"WAY4",'жами банкоматлар 2025'!$G:$G,"GRG P5800") -> 0 | L14: =COUNTIFS(Инфокиоски!$E:$E,$B14,Инфокиоски!$D:$D,"Touchplat")+COUNTIFS(Инфокиоски!$E:$E,$B14,Инфокиоски!$D:$D,"Optimal") -> 19
A15: 12 | B15: Фарғона вилояти | C15: =D15+E15+H15+I15+J15+K15 -> 0 | D15: =COUNTIFS('жами банкоматлар 2025'!$E:$E,$B15,'жами банкоматлар 2025'!$I:$I,"UzCard",'жами банкоматлар 2025'!$G:$G,"NCR 6623")+COUNTIFS('жами банкоматлар 2025'!$E:$E,$B15,'жами банкоматлар 2025'!$I:$I,"UzCard",'жами банкоматлар 2025'!$G:$G,"NCR 6622") -> 0 | E15: =COUNTIFS('жами банкоматлар 2025'!$E:$E,$B15,'жами банкоматлар 2025'!$I:$I,"UzCard",'жами банкоматлар 2025'!$G:$G,"CINEO C2070")+COUNTIFS('жами банкоматлар 2025'!$E:$E,$B15,'жами банкоматлар 2025'!$I:$I,"UzCard",'жами банкоматлар 2025'!$G:$G,"CINEO C4560") -> 0 | F15: 17 | G15: 0 | H15: =COUNTIFS('жами банкоматлар 2025'!$E:$E,$B15,'жами банкоматлар 2025'!$I:$I,"Humo",'жами банкоматлар 2025'!$G:$G,"NCR 6623")+COUNTIFS('жами банкоматлар 2025'!$E:$E,$B15,'жами банкоматлар 2025'!$I:$I,"Humo",'жами банкоматлар 2025'!$G:$G,"CINEO C2040") -> 0 | I15: =COUNTIFS('жами банкоматлар 2025'!$E:$E,$B15,'жами банкоматлар 2025'!$I:$I,"Humo",'жами банкоматлар 2025'!$G:$G,"NCR 6682")+COUNTIFS('жами банкоматлар 2025'!$E:$E,$B15,'жами банкоматлар 2025'!$I:$I,"Humo",'жами банкоматлар 2025'!$G:$G,"CINEO C2070")+COUNTIFS('жами банкоматлар 2025'!$E:$E,$B15,'жами банкоматлар 2025'!$I:$I,"Humo",'жами банкоматлар 2025'!$G:$G,"GRG P5800") -> 0 | J15: =COUNTIFS('жами банкоматлар 2025'!$E:$E,$B15,'жами банкоматлар 2025'!$I:$I,"WAY4",'жами банкоматлар 2025'!$G:$G,"NCR 6623") -> 0 | K15: =COUNTIFS('жами банкоматлар 2025'!$E:$E,$B15,'жами банкоматлар 2025'!$I:$I,"WAY4",'жами банкоматлар 2025'!$G:$G,"NCR 6682")+COUNTIFS('жами банкоматлар 2025'!$E:$E,$B15,'жами банкоматлар 2025'!$I:$I,"WAY4",'жами банкоматлар 2025'!$G:$G,"CINEO C2070")+COUNTIFS('жами банкоматлар 2025'!$E:$E,$B15,'жами банкоматлар 2025'!$I:$I,"WAY4",'жами банкоматлар 2025'!$G:$G,"GRG P5800") -> 0 | L15: =COUNTIFS(Инфокиоски!$E:$E,$B15,Инфокиоски!$D:$D,"Touchplat")+COUNTIFS(Инфокиоски!$E:$E,$B15,Инфокиоски!$D:$D,"Optimal") -> 15
A16: 13 | B16: Хоразм вилояти | C16: =D16+E16+H16+I16+J16+K16 -> 0 | D16: =COUNTIFS('жами банкоматлар 2025'!$E:$E,$B16,'жами банкоматлар 2025'!$I:$I,"UzCard",'жами банкоматлар 2025'!$G:$G,"NCR 6623")+COUNTIFS('жами банкоматлар 2025'!$E:$E,$B16,'жами банкоматлар 2025'!$I:$I,"UzCard",'жами банкоматлар 2025'!$G:$G,"NCR 6622") -> 0 | E16: =COUNTIFS('жами банкоматлар 2025'!$E:$E,$B16,'жами банкоматлар 2025'!$I:$I,"UzCard",'жами банкоматлар 2025'!$G:$G,"CINEO C2070")+COUNTIFS('жами банкоматлар 2025'!$E:$E,$B16,'жами банкоматлар 2025'!$I:$I,"UzCard",'жами банкоматлар 2025'!$G:$G,"CINEO C4560") -> 0 | F16: 6 | G16: 0 | H16: =COUNTIFS('жами банкоматлар 2025'!$E:$E,$B16,'жами банкоматлар 2025'!$I:$I,"Humo",'жами банкоматлар 2025'!$G:$G,"NCR 6623")+COUNTIFS('жами банкоматлар 2025'!$E:$E,$B16,'жами банкоматлар 2025'!$I:$I,"Humo",'жами банкоматлар 2025'!$G:$G,"CINEO C2040") -> 0 | I16: =COUNTIFS('жами банкоматлар 2025'!$E:$E,$B16,'жами банкоматлар 2025'!$I:$I,"Humo",'жами банкоматлар 2025'!$G:$G,"NCR 6682")+COUNTIFS('жами банкоматлар 2025'!$E:$E,$B16,'жами банкоматлар 2025'!$I:$I,"Humo",'жами банкоматлар 2025'!$G:$G,"CINEO C2070")+COUNTIFS('жами банкоматлар 2025'!$E:$E,$B16,'жами банкоматлар 2025'!$I:$I,"Humo",'жами банкоматлар 2025'!$G:$G,"GRG P5800") -> 0 | J16: =COUNTIFS('жами банкоматлар 2025'!$E:$E,$B16,'жами банкоматлар 2025'!$I:$I,"WAY4",'жами банкоматлар 2025'!$G:$G,"NCR 6623") -> 0 | K16: =COUNTIFS('жами банкоматлар 2025'!$E:$E,$B16,'жами банкоматлар 2025'!$I:$I,"WAY4",'жами банкоматлар 2025'!$G:$G,"NCR 6682")+COUNTIFS('жами банкоматлар 2025'!$E:$E,$B16,'жами банкоматлар 2025'!$I:$I,"WAY4",'жами банкоматлар 2025'!$G:$G,"CINEO C2070")+COUNTIFS('жами банкоматлар 2025'!$E:$E,$B16,'жами банкоматлар 2025'!$I:$I,"WAY4",'жами банкоматлар 2025'!$G:$G,"GRG P5800") -> 0 | L16: =COUNTIFS(Инфокиоски!$E:$E,$B16,Инфокиоски!$D:$D,"Touchplat")+COUNTIFS(Инфокиоски!$E:$E,$B16,Инфокиоски!$D:$D,"Optimal") -> 1
A17: 14 | B17: Тошкент шаҳри | C17: =D17+E17+H17+I17+J17+K17 -> 0 | D17: =COUNTIFS('жами банкоматлар 2025'!$E:$E,$B17,'жами банкоматлар 2025'!$I:$I,"UzCard",'жами банкоматлар 2025'!$G:$G,"NCR 6623")+COUNTIFS('жами банкоматлар 2025'!$E:$E,$B17,'жами банкоматлар 2025'!$I:$I,"UzCard",'жами банкоматлар 2025'!$G:$G,"NCR 6622") -> 0 | E17: =COUNTIFS('жами банкоматлар 2025'!$E:$E,$B17,'жами банкоматлар 2025'!$I:$I,"UzCard",'жами банкоматлар 2025'!$G:$G,"CINEO C2070")+COUNTIFS('жами банкоматлар 2025'!$E:$E,$B17,'жами банкоматлар 2025'!$I:$I,"UzCard",'жами банкоматлар 2025'!$G:$G,"CINEO C4560") -> 0 | F17: 48 | G17: 21 | H17: =COUNTIFS('жами банкоматлар 2025'!$E:$E,$B17,'жами банкоматлар 2025'!$I:$I,"Humo",'жами банкоматлар 2025'!$G:$G,"NCR 6623")+COUNTIFS('жами банкоматлар 2025'!$E:$E,$B17,'жами банкоматлар 2025'!$I:$I,"Humo",'жами банкоматлар 2025'!$G:$G,"CINEO C2040") -> 0 | I17: =COUNTIFS('жами банкоматлар 2025'!$E:$E,$B17,'жами банкоматлар 2025'!$I:$I,"Humo",'жами банкоматлар 2025'!$G:$G,"NCR 6682")+COUNTIFS('жами банкоматлар 2025'!$E:$E,$B17,'жами банкоматлар 2025'!$I:$I,"Humo",'жами банкоматлар 2025'!$G:$G,"CINEO C2070")+COUNTIFS('жами банкоматлар 2025'!$E:$E,$B17,'жами банкоматлар 2025'!$I:$I,"Humo",'жами банкоматлар 2025'!$G:$G,"GRG P5800") -> 0 | J17: =COUNTIFS('жами банкоматлар 2025'!$E:$E,$B17,'жами банкоматлар 2025'!$I:$I,"WAY4",'жами банкоматлар 2025'!$G:$G,"NCR 6623") -> 0 | K17: =COUNTIFS('жами банкоматлар 2025'!$E:$E,$B17,'жами банкоматлар 2025'!$I:$I,"WAY4",'жами банкоматлар 2025'!$G:$G,"NCR 6682")+COUNTIFS('жами банкоматлар 2025'!$E:$E,$B17,'жами банкоматлар 2025'!$I:$I,"WAY4",'жами банкоматлар 2025'!$G:$G,"CINEO C2070")+COUNTIFS('жами банкоматлар 2025'!$E:$E,$B17,'жами банкоматлар 2025'!$I:$I,"WAY4",'жами банкоматлар 2025'!$G:$G,"GRG P5800") -> 0 | L17: =COUNTIFS(Инфокиоски!$E:$E,$B17,Инфокиоски!$D:$D,"Touchplat")+COUNTIFS(Инфокиоски!$E:$E,$B17,Инфокиоски!$D:$D,"Optimal") -> 31
A18: Жами | C18: =D18+E18+H18+I18+J18+K18 -> 1 | D18: =SUM(D4:D17) -> 1 | E18: =SUM(E4:E17) -> 0 | F18: =SUM(F4:F17) -> 157 | G18: =SUM(G4:G17) -> 21 | H18: =SUM(H4:H17) -> 0 | I18: =SUM(I4:I17) -> 0 | J18: =SUM(J4:J17) -> 0 | K18: =SUM(K4:K17) -> 0 | L18: =SUM(L4:L17) -> 128

Sheet Инфокиоски
B1: Группа | F1: Киоск
A2: № | B2: МФО ф-л | C2: Названия филиала | D2: Модел киоска | E2: Регион | F2: Серийный номер | G2: Киоска ID | H2: MerchantID | I2: Terminal ID | J2: Terminal ID | K2: Адрес установки | L2: Ориентир | M2: Геолокация (alt) | N2: Геолокация (long)
A3: 1 | B3: 00051 | C3: Хонобод БХМ | D3: Touchplat | E3: Андижон вилояти | F3: 0008265 | G3: 10051001 | H3: 900346213 | I3: 95000968 | J3: 9005650 | K3: Хонобод ш Фароғат кўчаси 2 уй | L3: БХМ биносида | M3: 40.802868 | N3: 72.987355
A4: 2 | B4: 00051 | C4: Хонобод БХМ | D4: Touchplat | E4: Андижон вилояти | F4: 0008270 | G4: 10051002 | H4: 900346213 | I4: 95000967 | J4: 9005651 | K4: Фарогат кўча 2 уй | L4: Банк биноси | M4: 40.802868 | N4: 72.987355
A5: 3 | B5: 00076 | C5: Бунёдкор БХО | D5: OPTIMAL | E5: Андижон вилояти | F5: 2016509 | G5: 10075001 | H5: 900346216 | I5: 95001995 | K5: Андижон шахар, Юсуф Отабеков кўчаси, 74 | L5: Шахар шифохонаси | M5: 40.812403 | N5: 72.314667
A6: 4 | B6: 00076 | C6: Бунёдкор БХО | D6: OPTIMAL | E6: Андижон вилояти | F6: 2016510 | G6: 10075002 | H6: 900346216 | I6: 95001996 | K6: Андижон вилояти, Андижон шахар Бустон МФЙ Усмон Юсупов кучаси | L6: Андижон Шахар Dibir Озик овкат | M6: 40.769946 | N6: 72.379158
A7: 5 | B7: 00076 | C7: Бунёдкор БХО | D7: Touchplat | E7: Андижон вилояти | F7: 0008302 | G7: 10075003 | H7: 900346216 | I7: 95001994 | J7: 9005647 | K7: Андижон ш. Бобуршох кўча 36 уй | L7: Банк биноси | M7: 40.78147 | N7: 72.331291
A8: 6 | B8: 00076 | C8: Бунёдкор БХО | D8: OPTIMAL | E8: Андижон вилояти | F8: 2016507 | G8: 10076001 | H8: 900346216 | I8: 95001052 | K8: Андижон вилояти, Андижон шахар Ўзбекистон кўчаси 280А уй | L8: Бархаёт БХМ 24/7 | M8: 40.783684 | N8: 72.345349
A9: 7 | B9: 00076 | C9: Бунёдкор БХО | D9: OPTIMAL | E9: Андижон вилояти | F9: 2016508 | G9: 10076002 | H9: 900346216 | I9: 95001051 | K9: Андижон вилояти, Андижон шахар Буюк турон | L9: Янги бозор олдида | M9: 40.757742 | N9: 72.353561
A10: 8 | B10: 00076 | C10: Бунёдкор БХО | D10: Touchplat | E10: Андижон вилояти | F10: 0008366 | G10: 10076003 | H10: 900346216 | I10: 95000976 | J10: 9005652 | K10: Андижон вилояти, Андижон шахар Амур темур 24 уй | L10: Бунёдкор БХМ биноси 24/7 | M10: 40.760647 | N10: 72.348285
A11: 9 | B11: 00076 | C11: Бунёдкор БХО | D11: Touchplat | E11: Андижон вилояти | F11: 0008304 | G11: 10076004 | H11: 900346216 | I11: 95000975 | J11: 9005653 | K11: Андижон вилояти, Андижон шахар Амур темур 24 уй | L11: Бунёдкор БХМ биноси 24/7 | M11: 40.760647 | N11: 72.348285
A12: 10 | B12: 00076 | C12: Бунёдкор БХО | D12: Touchplat | E12: Андижон вилояти | F12: 0008300 | G12: 10076005 | H12: 900346216 | I12: 95000974 | J12: 9005654 | K12: Андижон вилояти, Андижон шахар, А.Юлдашева кўчаси | L12: Visus клиникаси | M12: 40.744138 | N12: 72.317809
A13: 11 | B13: 00085 | C13: Коровулбозор БХМ | D13: Touchplat | E13: Бухоро вилояти | F13: 0008295 | G13: 10085001 | H13: 900346218 | I13: 95000977 | J13: 9005656 | K13: Бухоро вилояти, Коровул Бозор туман Геологлар кучаси | L13: Коровулбозор Банк биноси | M13: 39.498571 | N13: 64.790155
A14: 12 | B14: 00862 | C14: Тўқимачилик БХМ | D14: Touchplat | E14: Бухоро вилояти | F14: 0008389 | G14: 10086004 | H14: 900381781 | I14: 95001962 | J14: 9005658 | K14: Когон шахар, Бухоро шох кўча 34 уй | L14: Когон БХМ | M14: 39.725665 | N14: 64.545167
A15: 13 | B15: 00085 | C15: Коровулбозор БХМ | D15: Touchplat | E15: Бухоро вилояти | F15: 0008319 | G15: 10085003 | H15: 900346218 | I15: 95000979 | J15: 9005657 | K15: Геологлар кўча 32 уй | L15: Банк биноси | M15: 39.498571 | N15: 64.790155
A16: 14 | B16: 00862 | C16: Тўқимачилик БХМ | D16: Touchplat | E16: Бухоро вилояти | F16: 0008283 | G16: 10086001 | H16: 900381781 | I16: 95001960 | J16: 9005655 | K16: город Бухара, улица Афросиаб | L16: ARK chicken кафе | M16: 39.779361 | N16: 64.410186
A17: 15 | B17: 00186 | C17: Муборак БХМ | D17: Touchplat | E17: Қашқадарё вилояти | F17: 0008284 | G17: 10186001 | H17: 900346229 | I17: 95000983 | J17: 9005692 | K17: Занжирсарой кўча 22 уй | L17: Банк биноси(омборда) | M17: 39.260139 | N17: 65.166091
A18: 16 | B18: 00186 | C18: Муборак БХМ | D18: Touchplat | E18: Қашқадарё вилояти | F18: 0008377 | G18: 10186002 | H18: 900346229 | I18: 95000982 | J18: 9005693 | K18: Қашқадарё вилояти, Муборак тумани промзонаси ИЭМ биноси | L18: ИЭМ биноси ичида | M18: 39.183162 | N18: 65.289318
A19: 17 | B19: 00186 | C19: Муборак БХМ | D19: Touchplat | E19: Қашқадарё вилояти | F19: 0008391 | G19: 10186003 | H19: 900346229 | I19: 95000981 | J19: 9005694 | K19: Занжирсарой кўча 22 уй | L19: Банк биноси | M19: 39.260139 | N19: 65.166091
A20: 18 | B20: 00186 | C20: Муборак БХМ | D20: Touchplat | E20: Қашқадарё вилояти | F20: 0008315 | G20: 10186004 | H20: 900346229 | I20: 95000980 | J20: 9005691 | K20: Занжирсарой кўча 22 уй | L20: Банк биноси | M20: 39.260139 | N20: 65.166091
A21: 19 | B21: 00207 | C21: Навоий БХО | D21: Touchplat | E21: Навоий вилояти | F21: 0008285 | G21: 10207001 | H21: 900318874 | I21: 95000102 | J21: 9005664 | K21: Навоий ш. Меъморлар кўча 7 уй | M21: 40.112964 | N21: 65.357957
A22: 20 | B22: 00207 | C22: Навоий БХО | D22: Touchplat | E22: Навоий вилояти | F22: 0008382 | G22: 10207002 | H22: 900318874 | I22: 95001046 | J22: 9005661 | K22: Навоий ш. Меъморлар кўча 17а уй | M22: 40.115806 | N22: 65.363726
A23: 21 | B23: 00207 | C23: Навоий БХО | D23: Touchplat | E23: Навоий вилояти | F23: 0008374 | G23: 10207003 | H23: 900318874 | I23: 95000111 | J23: 9005663 | K23: Навоий ш. И.Каримов кўча 7 уй | M23: 40.100793 | N23: 65.374877
A24: 22 | B24: 00207 | C24: Навоий БХО | D24: Touchplat | E24: Навоий вилояти | F24: 0008298 | G24: 10207004 | H24: 900318874 | I24: 95000110 | J24: 9005662 | K24: Навоий ш. Меъморлар кўча 7 уй | M24: 40.112964 | N24: 65.357957
A25: 23 | B25: 00224 | C25: Наманган БХО | D25: Touchplat | E25: Наманган вилояти | F25: 0008262 | G25: 10224001 | H25: 900346235 | I25: 95000988 | J25: 9005665 | K25: Наманган вилояти, Фурқат МФЙ, И.Каримов кўчаси ,19-уй | L25: Саноатқурилишбанк биноси олдида 24/7 | M25: 41.00586 | N25: 71.63588
A26: 24 | B26: 00224 | C26: Наманган БХО | D26: Touchplat | E26: Наманган вилояти | F26: 0008264 | G26: 10224002 | H26: 900346235 | I26: 95000987 | J26: 9005666 | K26: улица Саноат, 37 | L26: Шахар электр тармоқ | M26: 41.010836 | N26: 71.645056
A27: 25 | B27: 00224 | C27: Наманган БХО | D27: Touchplat | E27: Наманган вилояти | F27: 0008376 | G27: 10224003 | H27: 900346235 | I27: 95000986 | J27: 9005648 | K27: Б.Машраб кўча, вилоят хокимлиги ичида | L27: Вилоят хокимлиги ичида | M27: 41.000712 | N27: 71.673359
A28: 26 | B28: 00224 | C28: Наманган БХО | D28: Touchplat | E28: Наманган вилояти | F28: 0008362 | G28: 10224004 | H28: 900346235 | I28: 95000985 | J28: 9005649 | K28: Котира кўча, 9в уй | L28: Электр тармоқ | M28: 41.000537 | N28: 71.614044
A29: 27 | B29: 00317 | C29: Самарканд БХО | D29: Touchplat | E29: Самарқанд вилояти | F29: 0008282 | G29: 10317001 | H29: 900346367 | I29: 95001027 | J29: 9005667 | K29: Туркистон кўча 162 уй | L29: Банк биноси | M29: 39.647250 | N29: 66.934231
A30: 28 | B30: 00354 | C30: Сариосиё БХМ | D30: Touchplat | E30: Сурхондарё вилояти | F30: 0008365 | G30: 10354001 | H30: 900346355 | I30: 95001017 | J30: 9005701 | K30: Сурхандарё вилояти, Сариосиё туман А Каххор куча 7-уй | L30: Саноаткурилишбанк Сариосиё филиали биносида | M30: 38.403139 | N30: 67.963948
A31: 29 | B31: 00354 | C31: Сариосиё БХМ | D31: Touchplat | E31: Сурхондарё вилояти | F31: 0008307 | G31: 10354002 | H31: 900346355 | I31: 95001016 | J31: 9005700 | K31: Сурхандарё вилояти, Сариосиё туман Шаргун Шахтиёрлар куча 29 | L31: Шаргун БХМ | M31: 38.466982 | N31: 67.963450
A32: 30 | B32: 00354 | C32: Сариосиё БХМ | D32: Touchplat | E32: Сурхондарё вилояти | F32: 0008254 | G32: 10354003 | H32: 900346355 | I32: 95001015 | J32: 9005702 | K32: Сурхандарё вилояти, Сариосиё туман А Каххор куча 7-уй | L32: Саноаткурилишбанк Сариосиё филиали биносида | M32: 38.403139 | N32: 67.963948
A33: 31 | B33: 00434 | C33: Ал-Хоразмий БХМ( Сергели БХМ) | D33: Touchplat | E33: Тошкент шаҳри | F33: 0008395 | G33: 10403001 | H33: 900346266 | I33: 95000998 | J33: 9005733 | K33: Сергели туман Шокирариқ кўча 3 уй | L33: Банк биноси | M33: 41.218655 | N33: 69.223275
A34: 32 | B34: 00424 | C34: Тошкент шахар БХО (Юнусобод БХМ) | D34: OPTIMAL | E34: Тошкент шаҳри | F34: 2016423 | G34: 10428001 | H34: 900335859 | I34: 95000649 | J34: 9006703 | K34: Yunusobod Tumani A.Temur kuchasi | L34: Avtosalon Xumo | M34: 41.366267 | N34: 69.285625
A35: 33 | B35: 00424 | C35: Тошкент шахар БХО (Юнусобод БХМ) | D35: Touchplat | E35: Тошкент шаҳри | F35: 0008311 | G35: 10428002 | H35: 900335859 | I35: 95000964 | J35: 9005729 | K35: Юнусобод туман Учкахрамон кўча 7 уй | L35: Банк биноси | M35: 41.376463 | N35: 69.281053
A36: 34 | B36: 00424 | C36: Тошкент шахар БХО (Юнусобод БХМ(Олмазор)) | D36: Touchplat | E36: Тошкент шаҳри | F36: 0008268 | G36: 10428004 | H36: 900335859 | I36: 95001421 | J36: 9005739 | K36: Тошкент шахри, Олмазор тумани, Дилсарой кўчаси, 5 | L36: Олмазор туман прокуратураси | M36: 41.350590 | N36: 69.239023
A37: 35 | B37: 00424 | C37: Тошкент шахар БХО (Юнусобод БХМ(Олмазор)) | D37: Touchplat | E37: Тошкент шаҳри | F37: 0008276 | G37: 10428003 | H37: 900335859 | I37: 95001422 | J37: 9005738 | K37: О.Бобожонова кўча 10 уй | L37: Банк биноси | M37: 41.353043 | N37: 69.252419
A38: 36 | B38: 00424 | C38: Тошкент шахар БХО (Юнусобод БХМ(Шахристан)) | D38: Touchplat | E38: Тошкент шаҳри | F38: 0008364 | G38: 10428005 | H38: 900335859 | I38: 95001424 | K38: Юнусобод туман Чинобод кўча 49 уй | L38: Банк биноси | M38: 41.353190 | N38: 69.296338
A39: 37 | B39: 00424 | C39: Тошкент шахар БХО | D39: Touchplat | E39: Тошкент шаҳри | F39: 0008292 | G39: 10424001 | H39: 900318877 | I39: 95000677 | J39: 9005727 | K39: М.Улугбек туман М.Улугбек кўча 93 уй | L39: "Пойтахт" автосалони | M39: 41.346429 | N39: 69.346787
A40: 38 | B40: 00424 | C40: Тошкент шахар БХО | D40: Touchplat | E40: Тошкент шаҳри | F40: 0008397 | G40: 10424002 | H40: 900318877 | I40: 95000082 | J40: 9005732 | K40: М.Улугбек туман Мустакиллик кўча 5 уй | L40: Амир Темур метро бекати | M40: 41.312641 | N40: 69.282378
...

Sheet VTM, STM
B2: № | C2: № | D2: МФО | E2: МФО | F2: Худуд | G2: Филиал | I2: Модели | J2: % | K2: 50-100 $ | L2: Тўлов тизими тури | M2: Серия рақами | N2: Merchant id | O2: Term id | P2: МФО | Q2: Манзили | R2: Мўлжал | T2: Геолокация (alt) | U2: Геолокация (long) | V2: Транзит х/р (23504)
B3: 1 | C3: 1 | D3: 00424 | E3: 11184 | F3: Тошкент шаҳри | G3: Тошкент шахар худудий БХО | H3: Амалиёт Бошкармаси | I3: VTM DT-7000I60XL | J3: 1 | L3: HUMO | M3: 493324 | N3: 004400001164009 | O3: 027A1K2Q | P3: 00424 | Q3: Шайхонтохур т. И. Каримов кўча 5 уй | R3: Toshkent City | T3: 41.312309 | U3: 69.245667 | V3: 23504000100011640807 | W3: 10107000900011640807

Sheet СВОД формула
A1: № | B1: МФО | C1: Локал | D1: БХО / БХМ номи | E1: HUMO | K1: WAY4 | P1: UzCard | V1: Банкомат ЖАМИ | W1: инфокиоск Жами | X1: Терминал HUMO | Y1: Терминал UzCARD | Z1: DATACARD CE840 HUMO | AA1: DATACARD CE840UzCARD
E2: CINEO C2040 | F2: CINEO C2070 | G2: NCR 6623 | H2: NCR 6682 | I2: GRG P5800 | J2: ЖАМИ | K2: NCR 6623 | L2: NCR 6682 | M2: CINEO C2070 | N2: GRG P5800 | O2: ЖАМИ | P2: NCR 6622 | Q2: NCR 6623 | R2: NCR 6682 | S2: CINEO C2070 | T2: CINEO C4560 | U2: ЖАМИ
A3: 1 | B3: 00051 | C3: =VLOOKUP(B3,'жами банкоматлар 2025'!C:D,2,0) -> 11087 | D3: =VLOOKUP(B3,'жами банкоматлар 2025'!C:F,4,0) -> Хонобод БХМ | E3: =COUNTIFS('жами банкоматлар 2025'!$D:$D,$C3,'жами банкоматлар 2025'!$I:$I,"Humo",'жами банкоматлар 2025'!$G:$G,"CINEO C2040") -> 0 | F3: =COUNTIFS('жами банкоматлар 2025'!$D:$D,$C3,'жами банкоматлар 2025'!$I:$I,"Humo",'жами банкоматлар 2025'!$G:$G,"CINEO C2070") -> 0 | G3: =COUNTIFS('жами банкоматлар 2025'!$D:$D,$C3,'жами банкоматлар 2025'!$I:$I,"Humo",'жами банкоматлар 2025'!$G:$G,"NCR 6623") -> 0 | H3: =COUNTIFS('жами банкоматлар 2025'!$D:$D,$C3,'жами банкоматлар 2025'!$I:$I,"Humo",'жами банкоматлар 2025'!$G:$G,"NCR 6682") -> 0 | I3: =COUNTIFS('жами банкоматлар 2025'!$D:$D,$C3,'жами банкоматлар 2025'!$I:$I,"Humo",'жами банкоматлар 2025'!$G:$G,"GRG P5800") -> 0 | J3: =+E3+F3+G3+H3+I3 -> 0 | K3: =COUNTIFS('жами банкоматлар 2025'!$D:$D,$C3,'жами банкоматлар 2025'!$I:$I,"Way4",'жами банкоматлар 2025'!$G:$G,"NCR 6623") -> 0 | L3: =COUNTIFS('жами банкоматлар 2025'!$D:$D,$C3,'жами банкоматлар 2025'!$I:$I,"Way4",'жами банкоматлар 2025'!$G:$G,"NCR 6682") -> 0 | M3: =COUNTIFS('жами банкоматлар 2025'!$D:$D,$C3,'жами банкоматлар 2025'!$I:$I,"Way4",'жами банкоматлар 2025'!$G:$G,"CINEO C2070") -> 0 | N3: =COUNTIFS('жами банкоматлар 2025'!$D:$D,$C3,'жами банкоматлар 2025'!$I:$I,"Way4",'жами банкоматлар 2025'!$G:$G,"GRG P5800") -> 0 | O3: =+K3+L3+M3+N3 -> 0 | P3: =COUNTIFS('жами банкоматлар 2025'!$D:$D,$C3,'жами банкоматлар 2025'!$I:$I,"UzCard",'жами банкоматлар 2025'!$G:$G,"NCR 6622") -> 0 | Q3: =COUNTIFS('жами банкоматлар 2025'!$D:$D,$C3,'жами банкоматлар 2025'!$I:$I,"UzCard",'жами банкоматлар 2025'!$G:$G,"NCR 6623") -> 1 | R3: =COUNTIFS('жами банкоматлар 2025'!$D:$D,$C3,'жами банкоматлар 2025'!$I:$I,"UzCard",'жами банкоматлар 2025'!$G:$G,"NCR 6682") -> 0 | S3: =COUNTIFS('жами банкоматлар 2025'!$D:$D,$C3,'жами банкоматлар 2025'!$I:$I,"UzCard",'жами банкоматлар 2025'!$G:$G,"CINEO C2070") -> 0 | T3: =COUNTIFS('жами банкоматлар 2025'!$D:$D,$C3,'жами банкоматлар 2025'!$I:$I,"UzCard",'жами банкоматлар 2025'!$G:$G,"CINEO C4560") -> 0 | U3: =+P3+Q3+S3+T3 -> 1 | V3: =+U3+O3+J3 -> 1 | W3: 2 | X3: 148 | Y3: 215 | Z3: 1 | AA3: 1
A4: 2 | B4: 00075 | C4: 11081 | D4: Андижон БХО | E4: =COUNTIFS('жами банкоматлар 2025'!$D:$D,$C4,'жами банкоматлар 2025'!$I:$I,"Humo",'жами банкоматлар 2025'!$G:$G,"CINEO C2040") -> 0 | F4: =COUNTIFS('жами банкоматлар 2025'!$D:$D,$C4,'жами банкоматлар 2025'!$I:$I,"Humo",'жами банкоматлар 2025'!$G:$G,"CINEO C2070") -> 0 | G4: =COUNTIFS('жами банкоматлар 2025'!$D:$D,$C4,'жами банкоматлар 2025'!$I:$I,"Humo",'жами банкоматлар 2025'!$G:$G,"NCR 6623") -> 0 | H4: =COUNTIFS('жами банкоматлар 2025'!$D:$D,$C4,'жами банкоматлар 2025'!$I:$I,"Humo",'жами банкоматлар 2025'!$G:$G,"NCR 6682") -> 0 | I4: =COUNTIFS('жами банкоматлар 2025'!$D:$D,$C4,'жами банкоматлар 2025'!$I:$I,"Humo",'жами банкоматлар 2025'!$G:$G,"GRG P5800") -> 0 | J4: =+E4+F4+G4+H4+I4 -> 0 | K4: =COUNTIFS('жами банкоматлар 2025'!$D:$D,$C4,'жами банкоматлар 2025'!$I:$I,"Way4",'жами банкоматлар 2025'!$G:$G,"NCR 6623") -> 0 | L4: =COUNTIFS('жами банкоматлар 2025'!$D:$D,$C4,'жами банкоматлар 2025'!$I:$I,"Way4",'жами банкоматлар 2025'!$G:$G,"NCR 6682") -> 0 | M4: =COUNTIFS('жами банкоматлар 2025'!$D:$D,$C4,'жами банкоматлар 2025'!$I:$I,"Way4",'жами банкоматлар 2025'!$G:$G,"CINEO C2070") -> 0 | N4: =COUNTIFS('жами банкоматлар 2025'!$D:$D,$C4,'жами банкоматлар 2025'!$I:$I,"Way4",'жами банкоматлар 2025'!$G:$G,"GRG P5800") -> 0 | O4: =+K4+L4+M4+N4 -> 0 | P4: =COUNTIFS('жами банкоматлар 2025'!$D:$D,$C4,'жами банкоматлар 2025'!$I:$I,"UzCard",'жами банкоматлар 2025'!$G:$G,"NCR 6622") -> 0 | Q4: =COUNTIFS('жами банкоматлар 2025'!$D:$D,$C4,'жами банкоматлар 2025'!$I:$I,"UzCard",'жами банкоматлар 2025'!$G:$G,"NCR 6623") -> 0 | R4: =COUNTIFS('жами банкоматлар 2025'!$D:$D,$C4,'жами банкоматлар 2025'!$I:$I,"UzCard",'жами банкоматлар 2025'!$G:$G,"NCR 6682") -> 0 | S4: =COUNTIFS('жами банкоматлар 2025'!$D:$D,$C4,'жами банкоматлар 2025'!$I:$I,"UzCard",'жами банкоматлар 2025'!$G:$G,"CINEO C2070") -> 0 | T4: =COUNTIFS('жами банкоматлар 2025'!$D:$D,$C4,'жами банкоматлар 2025'!$I:$I,"UzCard",'жами банкоматлар 2025'!$G:$G,"CINEO C4560") -> 0 | U4: =+P4+Q4+S4+T4 -> 0 | V4: =+U4+O4+J4 -> 0 | W4: 3 | X4: 173 | Y4: 425 | Z4: 1 | AA4: 1
A5: 3 | B5: 00076 | C5: 11088 | D5: Бунёдкор БХО | E5: =COUNTIFS('жами банкоматлар 2025'!$D:$D,$C5,'жами банкоматлар 2025'!$I:$I,"Humo",'жами банкоматлар 2025'!$G:$G,"CINEO C2040") -> 0 | F5: =COUNTIFS('жами банкоматлар 2025'!$D:$D,$C5,'жами банкоматлар 2025'!$I:$I,"Humo",'жами банкоматлар 2025'!$G:$G,"CINEO C2070") -> 0 | G5: =COUNTIFS('жами банкоматлар 2025'!$D:$D,$C5,'жами банкоматлар 2025'!$I:$I,"Humo",'жами банкоматлар 2025'!$G:$G,"NCR 6623") -> 0 | H5: =COUNTIFS('жами банкоматлар 2025'!$D:$D,$C5,'жами банкоматлар 2025'!$I:$I,"Humo",'жами банкоматлар 2025'!$G:$G,"NCR 6682") -> 0 | I5: =COUNTIFS('жами банкоматлар 2025'!$D:$D,$C5,'жами банкоматлар 2025'!$I:$I,"Humo",'жами банкоматлар 2025'!$G:$G,"GRG P5800") -> 0 | J5: =+E5+F5+G5+H5+I5 -> 0 | K5: =COUNTIFS('жами банкоматлар 2025'!$D:$D,$C5,'жами банкоматлар 2025'!$I:$I,"Way4",'жами банкоматлар 2025'!$G:$G,"NCR 6623") -> 0 | L5: =COUNTIFS('жами банкоматлар 2025'!$D:$D,$C5,'жами банкоматлар 2025'!$I:$I,"Way4",'жами банкоматлар 2025'!$G:$G,"NCR 6682") -> 0 | M5: =COUNTIFS('жами банкоматлар 2025'!$D:$D,$C5,'жами банкоматлар 2025'!$I:$I,"Way4",'жами банкоматлар 2025'!$G:$G,"CINEO C2070") -> 0 | N5: =COUNTIFS('жами банкоматлар 2025'!$D:$D,$C5,'жами банкоматлар 2025'!$I:$I,"Way4",'жами банкоматлар 2025'!$G:$G,"GRG P5800") -> 0 | O5: =+K5+L5+M5+N5 -> 0 | P5: =COUNTIFS('жами банкоматлар 2025'!$D:$D,$C5,'жами банкоматлар 2025'!$I:$I,"UzCard",'жами банкоматлар 2025'!$G:$G,"NCR 6622") -> 0 | Q5: =COUNTIFS('жами банкоматлар 2025'!$D:$D,$C5,'жами банкоматлар 2025'!$I:$I,"UzCard",'жами банкоматлар 2025'!$G:$G,"NCR 6623") -> 0 | R5: =COUNTIFS('жами банкоматлар 2025'!$D:$D,$C5,'жами банкоматлар 2025'!$I:$I,"UzCard",'жами банкоматлар 2025'!$G:$G,"NCR 6682") -> 0 | S5: =COUNTIFS('жами банкоматлар 2025'!$D:$D,$C5,'жами банкоматлар 2025'!$I:$I,"UzCard",'жами банкоматлар 2025'!$G:$G,"CINEO C2070") -> 0 | T5: =COUNTIFS('жами банкоматлар 2025'!$D:$D,$C5,'жами банкоматлар 2025'!$I:$I,"UzCard",'жами банкоматлар 2025'!$G:$G,"CINEO C4560") -> 0 | U5: =+P5+Q5+S5+T5 -> 0 | V5: =+U5+O5+J5 -> 0 | W5: 5 | X5: 176 | Y5: 217 | Z5: 0 | AA5: 1
A6: 4 | B6: 00085 | C6: =VLOOKUP(B6,'жами банкоматлар 2025'!C:D,2,0) -> #N/A | D6: =VLOOKUP(B6,'жами банкоматлар 2025'!C:F,4,0) -> #N/A | E6: =COUNTIFS('жами банкоматлар 2025'!$D:$D,$C6,'жами банкоматлар 2025'!$I:$I,"Humo",'жами банкоматлар 2025'!$G:$G,"CINEO C2040") -> 0 | F6: =COUNTIFS('жами банкоматлар 2025'!$D:$D,$C6,'жами банкоматлар 2025'!$I:$I,"Humo",'жами банкоматлар 2025'!$G:$G,"CINEO C2070") -> 0 | G6: =COUNTIFS('жами банкоматлар 2025'!$D:$D,$C6,'жами банкоматлар 2025'!$I:$I,"Humo",'жами банкоматлар 2025'!$G:$G,"NCR 6623") -> 0 | H6: =COUNTIFS('жами банкоматлар 2025'!$D:$D,$C6,'жами банкоматлар 2025'!$I:$I,"Humo",'жами банкоматлар 2025'!$G:$G,"NCR 6682") -> 0 | I6: =COUNTIFS('жами банкоматлар 2025'!$D:$D,$C6,'жами банкоматлар 2025'!$I:$I,"Humo",'жами банкоматлар 2025'!$G:$G,"GRG P5800") -> 0 | J6: =+E6+F6+G6+H6+I6 -> 0 | K6: =COUNTIFS('жами банкоматлар 2025'!$D:$D,$C6,'жами банкоматлар 2025'!$I:$I,"Way4",'жами банкоматлар 2025'!$G:$G,"NCR 6623") -> 0 | L6: =COUNTIFS('жами банкоматлар 2025'!$D:$D,$C6,'жами банкоматлар 2025'!$I:$I,"Way4",'жами банкоматлар 2025'!$G:$G,"NCR 6682") -> 0 | M6: =COUNTIFS('жами банкоматлар 2025'!$D:$D,$C6,'жами банкоматлар 2025'!$I:$I,"Way4",'жами банкоматлар 2025'!$G:$G,"CINEO C2070") -> 0 | N6: =COUNTIFS('жами банкоматлар 2025'!$D:$D,$C6,'жами банкоматлар 2025'!$I:$I,"Way4",'жами банкоматлар 2025'!$G:$G,"GRG P5800") -> 0 | O6: =+K6+L6+M6+N6 -> 0 | P6: =COUNTIFS('жами банкоматлар 2025'!$D:$D,$C6,'жами банкоматлар 2025'!$I:$I,"UzCard",'жами банкоматлар 2025'!$G:$G,"NCR 6622") -> 0 | Q6: =COUNTIFS('жами банкоматлар 2025'!$D:$D,$C6,'жами банкоматлар 2025'!$I:$I,"UzCard",'жами банкоматлар 2025'!$G:$G,"NCR 6623") -> 0 | R6: =COUNTIFS('жами банкоматлар 2025'!$D:$D,$C6,'жами банкоматлар 2025'!$I:$I,"UzCard",'жами банкоматлар 2025'!$G:$G,"NCR 6682") -> 0 | S6: =COUNTIFS('жами банкоматлар 2025'!$D:$D,$C6,'жами банкоматлар 2025'!$I:$I,"UzCard",'жами банкоматлар 2025'!$G:$G,"CINEO C2070") -> 0 | T6: =COUNTIFS('жами банкоматлар 2025'!$D:$D,$C6,'жами банкоматлар 2025'!$I:$I,"UzCard",'жами банкоматлар 2025'!$G:$G,"CINEO C4560") -> 0 | U6: =+P6+Q6+S6+T6 -> 0 | V6: =+U6+O6+J6 -> 0 | W6: 3 | X6: 250 | Y6: 215 | Z6: 1 | AA6: 1
A7: 5 | B7: 00086 | C7: 10852 | D7: Бухоро БХО | E7: =COUNTIFS('жами банкоматлар 2025'!$D:$D,$C7,'жами банкоматлар 2025'!$I:$I,"Humo",'жами банкоматлар 2025'!$G:$G,"CINEO C2040") -> 0 | F7: =COUNTIFS('жами банкоматлар 2025'!$D:$D,$C7,'жами банкоматлар 2025'!$I:$I,"Humo",'жами банкоматлар 2025'!$G:$G,"CINEO C2070") -> 0 | G7: =COUNTIFS('жами банкоматлар 2025'!$D:$D,$C7,'жами банкоматлар 2025'!$I:$I,"Humo",'жами банкоматлар 2025'!$G:$G,"NCR 6623") -> 0 | H7: =COUNTIFS('жами банкоматлар 2025'!$D:$D,$C7,'жами банкоматлар 2025'!$I:$I,"Humo",'жами банкоматлар 2025'!$G:$G,"NCR 6682") -> 0 | I7: =COUNTIFS('жами банкоматлар 2025'!$D:$D,$C7,'жами банкоматлар 2025'!$I:$I,"Humo",'жами банкоматлар 2025'!$G:$G,"GRG P5800") -> 0 | J7: =+E7+F7+G7+H7+I7 -> 0 | K7: =COUNTIFS('жами банкоматлар 2025'!$D:$D,$C7,'жами банкоматлар 2025'!$I:$I,"Way4",'жами банкоматлар 2025'!$G:$G,"NCR 6623") -> 0 | L7: =COUNTIFS('жами банкоматлар 2025'!$D:$D,$C7,'жами банкоматлар 2025'!$I:$I,"Way4",'жами банкоматлар 2025'!$G:$G,"NCR 6682") -> 0 | M7: =COUNTIFS('жами банкоматлар 2025'!$D:$D,$C7,'жами банкоматлар 2025'!$I:$I,"Way4",'жами банкоматлар 2025'!$G:$G,"CINEO C2070") -> 0 | N7: =COUNTIFS('жами банкоматлар 2025'!$D:$D,$C7,'жами банкоматлар 2025'!$I:$I,"Way4",'жами банкоматлар 2025'!$G:$G,"GRG P5800") -> 0 | O7: =+K7+L7+M7+N7 -> 0 | P7: =COUNTIFS('жами банкоматлар 2025'!$D:$D,$C7,'жами банкоматлар 2025'!$I:$I,"UzCard",'жами банкоматлар 2025'!$G:$G,"NCR 6622") -> 0 | Q7: =COUNTIFS('жами банкоматлар 2025'!$D:$D,$C7,'жами банкоматлар 2025'!$I:$I,"UzCard",'жами банкоматлар 2025'!$G:$G,"NCR 6623") -> 0 | R7: =COUNTIFS('жами банкоматлар 2025'!$D:$D,$C7,'жами банкоматлар 2025'!$I:$I,"UzCard",'жами банкоматлар 2025'!$G:$G,"NCR 6682") -> 0 | S7: =COUNTIFS('жами банкоматлар 2025'!$D:$D,$C7,'жами банкоматлар 2025'!$I:$I,"UzCard",'жами банкоматлар 2025'!$G:$G,"CINEO C2070") -> 0 | T7: =COUNTIFS('жами банкоматлар 2025'!$D:$D,$C7,'жами банкоматлар 2025'!$I:$I,"UzCard",'жами банкоматлар 2025'!$G:$G,"CINEO C4560") -> 0 | U7: =+P7+Q7+S7+T7 -> 0 | V7: =+U7+O7+J7 -> 0 | W7: 1 | X7: 555 | Y7: 599 | Z7: 1 | AA7: 1
A8: 6 | B8: 00207 | C8: =VLOOKUP(B8,'жами банкоматлар 2025'!C:D,2,0) -> #N/A | D8: =VLOOKUP(B8,'жами банкоматлар 2025'!C:F,4,0) -> #N/A | E8: =COUNTIFS('жами банкоматлар 2025'!$D:$D,$C8,'жами банкоматлар 2025'!$I:$I,"Humo",'жами банкоматлар 2025'!$G:$G,"CINEO C2040") -> 0 | F8: =COUNTIFS('жами банкоматлар 2025'!$D:$D,$C8,'жами банкоматлар 2025'!$I:$I,"Humo",'жами банкоматлар 2025'!$G:$G,"CINEO C2070") -> 0 | G8: =COUNTIFS('жами банкоматлар 2025'!$D:$D,$C8,'жами банкоматлар 2025'!$I:$I,"Humo",'жами банкоматлар 2025'!$G:$G,"NCR 6623") -> 0 | H8: =COUNTIFS('жами банкоматлар 2025'!$D:$D,$C8,'жами банкоматлар 2025'!$I:$I,"Humo",'жами банкоматлар 2025'!$G:$G,"NCR 6682") -> 0 | I8: =COUNTIFS('жами банкоматлар 2025'!$D:$D,$C8,'жами банкоматлар 2025'!$I:$I,"Humo",'жами банкоматлар 2025'!$G:$G,"GRG P5800") -> 0 | J8: =+E8+F8+G8+H8+I8 -> 0 | K8: =COUNTIFS('жами банкоматлар 2025'!$D:$D,$C8,'жами банкоматлар 2025'!$I:$I,"Way4",'жами банкоматлар 2025'!$G:$G,"NCR 6623") -> 0 | L8: =COUNTIFS('жами банкоматлар 2025'!$D:$D,$C8,'жами банкоматлар 2025'!$I:$I,"Way4",'жами банкоматлар 2025'!$G:$G,"NCR 6682") -> 0 | M8: =COUNTIFS('жами банкоматлар 2025'!$D:$D,$C8,'жами банкоматлар 2025'!$I:$I,"Way4",'жами банкоматлар 2025'!$G:$G,"CINEO C2070") -> 0 | N8: =COUNTIFS('жами банкоматлар 2025'!$D:$D,$C8,'жами банкоматлар 2025'!$I:$I,"Way4",'жами банкоматлар 2025'!$G:$G,"GRG P5800") -> 0 | O8: =+K8+L8+M8+N8 -> 0 | P8: =COUNTIFS('жами банкоматлар 2025'!$D:$D,$C8,'жами банкоматлар 2025'!$I:$I,"UzCard",'жами банкоматлар 2025'!$G:$G,"NCR 6622") -> 0 | Q8: =COUNTIFS('жами банкоматлар 2025'!$D:$D,$C8,'жами банкоматлар 2025'!$I:$I,"UzCard",'жами банкоматлар 2025'!$G:$G,"NCR 6623") -> 0 | R8: =COUNTIFS('жами банкоматлар 2025'!$D:$D,$C8,'жами банкоматлар 2025'!$I:$I,"UzCard",'жами банкоматлар 2025'!$G:$G,"NCR 6682") -> 0 | S8: =COUNTIFS('жами банкоматлар 2025'!$D:$D,$C8,'жами банкоматлар 2025'!$I:$I,"UzCard",'жами банкоматлар 2025'!$G:$G,"CINEO C2070") -> 0 | T8: =COUNTIFS('жами банкоматлар 2025'!$D:$D,$C8,'жами банкоматлар 2025'!$I:$I,"UzCard",'жами банкоматлар 2025'!$G:$G,"CINEO C4560") -> 0 | U8: =+P8+Q8+R8+S8+T8 -> 0 | V8: =+U8+O8+J8 -> 0 | W8: 4 | X8: 326 | Y8: 567 | Z8: 1 | AA8: 1
A9: 7 | B9: 00224 | C9: =VLOOKUP(B9,'жами банкоматлар 2025'!C:D,2,0) -> #N/A | D9: =VLOOKUP(B9,'жами банкоматлар 2025'!C:F,4,0) -> #N/A | E9: =COUNTIFS('жами банкоматлар 2025'!$D:$D,$C9,'жами банкоматлар 2025'!$I:$I,"Humo",'жами банкоматлар 2025'!$G:$G,"CINEO C2040") -> 0 | F9: =COUNTIFS('жами банкоматлар 2025'!$D:$D,$C9,'жами банкоматлар 2025'!$I:$I,"Humo",'жами банкоматлар 2025'!$G:$G,"CINEO C2070") -> 0 | G9: =COUNTIFS('жами банкоматлар 2025'!$D:$D,$C9,'жами банкоматлар 2025'!$I:$I,"Humo",'жами банкоматлар 2025'!$G:$G,"NCR 6623") -> 0 | H9: =COUNTIFS('жами банкоматлар 2025'!$D:$D,$C9,'жами банкоматлар 2025'!$I:$I,"Humo",'жами банкоматлар 2025'!$G:$G,"NCR 6682") -> 0 | I9: =COUNTIFS('жами банкоматлар 2025'!$D:$D,$C9,'жами банкоматлар 2025'!$I:$I,"Humo",'жами банкоматлар 2025'!$G:$G,"GRG P5800") -> 0 | J9: =+E9+F9+G9+H9+I9 -> 0 | K9: =COUNTIFS('жами банкоматлар 2025'!$D:$D,$C9,'жами банкоматлар 2025'!$I:$I,"Way4",'жами банкоматлар 2025'!$G:$G,"NCR 6623") -> 0 | L9: =COUNTIFS('жами банкоматлар 2025'!$D:$D,$C9,'жами банкоматлар 2025'!$I:$I,"Way4",'жами банкоматлар 2025'!$G:$G,"NCR 6682") -> 0 | M9: =COUNTIFS('жами банкоматлар 2025'!$D:$D,$C9,'жами банкоматлар 2025'!$I:$I,"Way4",'жами банкоматлар 2025'!$G:$G,"CINEO C2070") -> 0 | N9: =COUNTIFS('жами банкоматлар 2025'!$D:$D,$C9,'жами банкоматлар 2025'!$I:$I,"Way4",'жами банкоматлар 2025'!$G:$G,"GRG P5800") -> 0 | O9: =+K9+L9+M9+N9 -> 0 | P9: =COUNTIFS('жами банкоматлар 2025'!$D:$D,$C9,'жами банкоматлар 2025'!$I:$I,"UzCard",'жами банкоматлар 2025'!$G:$G,"NCR 6622") -> 0 | Q9: =COUNTIFS('жами банкоматлар 2025'!$D:$D,$C9,'жами банкоматлар 2025'!$I:$I,"UzCard",'жами банкоматлар 2025'!$G:$G,"NCR 6623") -> 0 | R9: =COUNTIFS('жами банкоматлар 2025'!$D:$D,$C9,'жами банкоматлар 2025'!$I:$I,"UzCard",'жами банкоматлар 2025'!$G:$G,"NCR 6682") -> 0 | S9: =COUNTIFS('жами банкоматлар 2025'!$D:$D,$C9,'жами банкоматлар 2025'!$I:$I,"UzCard",'жами банкоматлар 2025'!$G:$G,"CINEO C2070") -> 0 | T9: =COUNTIFS('жами банкоматлар 2025'!$D:$D,$C9,'жами банкоматлар 2025'!$I:$I,"UzCard",'жами банкоматлар 2025'!$G:$G,"CINEO C4560") -> 0 | U9: =+P9+Q9+S9+T9 -> 0 | V9: =+U9+O9+J9 -> 0 | W9: 4 | X9: 237 | Y9: 470 | Z9: 1 | AA9: 1
A10: 8 | B10: 00354 | C10: =VLOOKUP(B10,'жами банкоматлар 2025'!C:D,2,0) -> #N/A | D10: =VLOOKUP(B10,'жами банкоматлар 2025'!C:F,4,0) -> #N/A | E10: =COUNTIFS('жами банкоматлар 2025'!$D:$D,$C10,'жами банкоматлар 2025'!$I:$I,"Humo",'жами банкоматлар 2025'!$G:$G,"CINEO C2040") -> 0 | F10: =COUNTIFS('жами банкоматлар 2025'!$D:$D,$C10,'жами банкоматлар 2025'!$I:$I,"Humo",'жами банкоматлар 2025'!$G:$G,"CINEO C2070") -> 0 | G10: =COUNTIFS('жами банкоматлар 2025'!$D:$D,$C10,'жами банкоматлар 2025'!$I:$I,"Humo",'жами банкоматлар 2025'!$G:$G,"NCR 6623") -> 0 | H10: =COUNTIFS('жами банкоматлар 2025'!$D:$D,$C10,'жами банкоматлар 2025'!$I:$I,"Humo",'жами банкоматлар 2025'!$G:$G,"NCR 6682") -> 0 | I10: =COUNTIFS('жами банкоматлар 2025'!$D:$D,$C10,'жами банкоматлар 2025'!$I:$I,"Humo",'жами банкоматлар 2025'!$G:$G,"GRG P5800") -> 0 | J10: =+E10+F10+G10+H10+I10 -> 0 | K10: =COUNTIFS('жами банкоматлар 2025'!$D:$D,$C10,'жами банкоматлар 2025'!$I:$I,"Way4",'жами банкоматлар 2025'!$G:$G,"NCR 6623") -> 0 | L10: =COUNTIFS('жами банкоматлар 2025'!$D:$D,$C10,'жами банкоматлар 2025'!$I:$I,"Way4",'жами банкоматлар 2025'!$G:$G,"NCR 6682") -> 0 | M10: =COUNTIFS('жами банкоматлар 2025'!$D:$D,$C10,'жами банкоматлар 2025'!$I:$I,"Way4",'жами банкоматлар 2025'!$G:$G,"CINEO C2070") -> 0 | N10: =COUNTIFS('жами банкоматлар 2025'!$D:$D,$C10,'жами банкоматлар 2025'!$I:$I,"Way4",'жами банкоматлар 2025'!$G:$G,"GRG P5800") -> 0 | O10: =+K10+L10+M10+N10 -> 0 | P10: =COUNTIFS('жами банкоматлар 2025'!$D:$D,$C10,'жами банкоматлар 2025'!$I:$I,"UzCard",'жами банкоматлар 2025'!$G:$G,"NCR 6622") -> 0 | Q10: =COUNTIFS('жами банкоматлар 2025'!$D:$D,$C10,'жами банкоматлар 2025'!$I:$I,"UzCard",'жами банкоматлар 2025'!$G:$G,"NCR 6623") -> 0 | R10: =COUNTIFS('жами банкоматлар 2025'!$D:$D,$C10,'жами банкоматлар 2025'!$I:$I,"UzCard",'жами банкоматлар 2025'!$G:$G,"NCR 6682") -> 0 | S10: =COUNTIFS('жами банкоматлар 2025'!$D:$D,$C10,'жами банкоматлар 2025'!$I:$I,"UzCard",'жами банкоматлар 2025'!$G:$G,"CINEO C2070") -> 0 | T10: =COUNTIFS('жами банкоматлар 2025'!$D:$D,$C10,'жами банкоматлар 2025'!$I:$I,"UzCard",'жами банкоматлар 2025'!$G:$G,"CINEO C4560") -> 0 | U10: =+P10+Q10+S10+T10 -> 0 | V10: =+U10+O10+J10 -> 0 | W10: 3 | X10: 394 | Y10: 386 | Z10: 1 | AA10: 1
A11: 9 | B11: 00494 | C11: 11082 | D11: Фарғона худудий БХО | E11: =COUNTIFS('жами банкоматлар 2025'!$D:$D,$C11,'жами банкоматлар 2025'!$I:$I,"Humo",'жами банкоматлар 2025'!$G:$G,"CINEO C2040") -> 0 | F11: =COUNTIFS('жами банкоматлар 2025'!$D:$D,$C11,'жами банкоматлар 2025'!$I:$I,"Humo",'жами банкоматлар 2025'!$G:$G,"CINEO C2070") -> 0 | G11: =COUNTIFS('жами банкоматлар 2025'!$D:$D,$C11,'жами банкоматлар 2025'!$I:$I,"Humo",'жами банкоматлар 2025'!$G:$G,"NCR 6623") -> 0 | H11: =COUNTIFS('жами банкоматлар 2025'!$D:$D,$C11,'жами банкоматлар 2025'!$I:$I,"Humo",'жами банкоматлар 2025'!$G:$G,"NCR 6682") -> 0 | I11: =COUNTIFS('жами банкоматлар 2025'!$D:$D,$C11,'жами банкоматлар 2025'!$I:$I,"Humo",'жами банкоматлар 2025'!$G:$G,"GRG P5800") -> 0 | J11: =+E11+F11+G11+H11+I11 -> 0 | K11: =COUNTIFS('жами банкоматлар 2025'!$D:$D,$C11,'жами банкоматлар 2025'!$I:$I,"Way4",'жами банкоматлар 2025'!$G:$G,"NCR 6623") -> 0 | L11: =COUNTIFS('жами банкоматлар 2025'!$D:$D,$C11,'жами банкоматлар 2025'!$I:$I,"Way4",'жами банкоматлар 2025'!$G:$G,"NCR 6682") -> 0 | M11: =COUNTIFS('жами банкоматлар 2025'!$D:$D,$C11,'жами банкоматлар 2025'!$I:$I,"Way4",'жами банкоматлар 2025'!$G:$G,"CINEO C2070") -> 0 | N11: =COUNTIFS('жами банкоматлар 2025'!$D:$D,$C11,'жами банкоматлар 2025'!$I:$I,"Way4",'жами банкоматлар 2025'!$G:$G,"GRG P5800") -> 0 | O11: =+K11+L11+M11+N11 -> 0 | P11: =COUNTIFS('жами банкоматлар 2025'!$D:$D,$C11,'жами банкоматлар 2025'!$I:$I,"UzCard",'жами банкоматлар 2025'!$G:$G,"NCR 6622") -> 0 | Q11: =COUNTIFS('жами банкоматлар 2025'!$D:$D,$C11,'жами банкоматлар 2025'!$I:$I,"UzCard",'жами банкоматлар 2025'!$G:$G,"NCR 6623") -> 0 | R11: =COUNTIFS('жами банкоматлар 2025'!$D:$D,$C11,'жами банкоматлар 2025'!$I:$I,"UzCard",'жами банкоматлар 2025'!$G:$G,"NCR 6682") -> 0 | S11: =COUNTIFS('жами банкоматлар 2025'!$D:$D,$C11,'жами банкоматлар 2025'!$I:$I,"UzCard",'жами банкоматлар 2025'!$G:$G,"CINEO C2070") -> 0 | T11: =COUNTIFS('жами банкоматлар 2025'!$D:$D,$C11,'жами банкоматлар 2025'!$I:$I,"UzCard",'жами банкоматлар 2025'!$G:$G,"CINEO C4560") -> 0 | U11: =+P11+Q11+S11+T11 -> 0 | V11: =+U11+O11+J11 -> 0 | W11: 7 | X11: 220 | Y11: 330 | Z11: 1 | AA11: 1
